Traceback (most recent call last):
  File "/usr/bin/gunicorn", line 7, in <module>
    from gunicorn.app.wsgiapp import run
ImportError: No module named 'gunicorn'
Traceback (most recent call last):
  File "/usr/bin/gunicorn", line 7, in <module>
    from gunicorn.app.wsgiapp import run
ImportError: No module named 'gunicorn'
Traceback (most recent call last):
  File "/usr/bin/gunicorn", line 7, in <module>
    from gunicorn.app.wsgiapp import run
ImportError: No module named 'gunicorn'
Traceback (most recent call last):
  File "/usr/bin/gunicorn", line 7, in <module>
    from gunicorn.app.wsgiapp import run
ImportError: No module named 'gunicorn'
[2018-09-19 13:19:03 +0000] [14823] [INFO] Starting gunicorn 19.4.5
[2018-09-19 13:19:03 +0000] [14823] [INFO] Listening at: http://0.0.0.0:2345 (14823)
[2018-09-19 13:19:03 +0000] [14823] [INFO] Using worker: sync
[2018-09-19 13:19:03 +0000] [14827] [INFO] Booting worker with pid: 14827
[2018-09-19 13:19:03 +0000] [14827] [ERROR] Exception in worker process:
Traceback (most recent call last):
  File "/usr/lib/python2.7/dist-packages/gunicorn/arbiter.py", line 515, in spawn_worker
    worker.init_process()
  File "/usr/lib/python2.7/dist-packages/gunicorn/workers/base.py", line 122, in init_process
    self.load_wsgi()
  File "/usr/lib/python2.7/dist-packages/gunicorn/workers/base.py", line 130, in load_wsgi
    self.wsgi = self.app.wsgi()
  File "/usr/lib/python2.7/dist-packages/gunicorn/app/base.py", line 67, in wsgi
    self.callable = self.load()
  File "/usr/lib/python2.7/dist-packages/gunicorn/app/wsgiapp.py", line 65, in load
    return self.load_wsgiapp()
  File "/usr/lib/python2.7/dist-packages/gunicorn/app/wsgiapp.py", line 52, in load_wsgiapp
    return util.import_app(self.app_uri)
  File "/usr/lib/python2.7/dist-packages/gunicorn/util.py", line 366, in import_app
    __import__(module)
  File "/home/intel/xytao/hsdes.py", line 26
    def query(self, eql_json: dict, max_results: int = 1000)->dict:
                            ^
SyntaxError: invalid syntax
Traceback (most recent call last):
  File "/usr/lib/python2.7/dist-packages/gunicorn/arbiter.py", line 515, in spawn_worker
    worker.init_process()
  File "/usr/lib/python2.7/dist-packages/gunicorn/workers/base.py", line 122, in init_process
    self.load_wsgi()
  File "/usr/lib/python2.7/dist-packages/gunicorn/workers/base.py", line 130, in load_wsgi
    self.wsgi = self.app.wsgi()
  File "/usr/lib/python2.7/dist-packages/gunicorn/app/base.py", line 67, in wsgi
    self.callable = self.load()
  File "/usr/lib/python2.7/dist-packages/gunicorn/app/wsgiapp.py", line 65, in load
    return self.load_wsgiapp()
  File "/usr/lib/python2.7/dist-packages/gunicorn/app/wsgiapp.py", line 52, in load_wsgiapp
    return util.import_app(self.app_uri)
  File "/usr/lib/python2.7/dist-packages/gunicorn/util.py", line 366, in import_app
    __import__(module)
  File "/home/intel/xytao/hsdes.py", line 26
    def query(self, eql_json: dict, max_results: int = 1000)->dict:
                            ^
SyntaxError: invalid syntax
[2018-09-19 13:19:03 +0000] [14827] [INFO] Worker exiting (pid: 14827)
[2018-09-19 13:19:03 +0000] [14823] [INFO] Shutting down: Master
[2018-09-19 13:19:03 +0000] [14823] [INFO] Reason: Worker failed to boot.
[2018-09-19 13:19:04 +0000] [14828] [INFO] Starting gunicorn 19.4.5
[2018-09-19 13:19:04 +0000] [14828] [INFO] Listening at: http://0.0.0.0:2345 (14828)
[2018-09-19 13:19:04 +0000] [14828] [INFO] Using worker: sync
[2018-09-19 13:19:04 +0000] [14832] [INFO] Booting worker with pid: 14832
[2018-09-19 13:19:04 +0000] [14832] [ERROR] Exception in worker process:
Traceback (most recent call last):
  File "/usr/lib/python2.7/dist-packages/gunicorn/arbiter.py", line 515, in spawn_worker
    worker.init_process()
  File "/usr/lib/python2.7/dist-packages/gunicorn/workers/base.py", line 122, in init_process
    self.load_wsgi()
  File "/usr/lib/python2.7/dist-packages/gunicorn/workers/base.py", line 130, in load_wsgi
    self.wsgi = self.app.wsgi()
  File "/usr/lib/python2.7/dist-packages/gunicorn/app/base.py", line 67, in wsgi
    self.callable = self.load()
  File "/usr/lib/python2.7/dist-packages/gunicorn/app/wsgiapp.py", line 65, in load
    return self.load_wsgiapp()
  File "/usr/lib/python2.7/dist-packages/gunicorn/app/wsgiapp.py", line 52, in load_wsgiapp
    return util.import_app(self.app_uri)
  File "/usr/lib/python2.7/dist-packages/gunicorn/util.py", line 366, in import_app
    __import__(module)
  File "/home/intel/xytao/hsdes.py", line 26
    def query(self, eql_json: dict, max_results: int = 1000)->dict:
                            ^
SyntaxError: invalid syntax
Traceback (most recent call last):
  File "/usr/lib/python2.7/dist-packages/gunicorn/arbiter.py", line 515, in spawn_worker
    worker.init_process()
  File "/usr/lib/python2.7/dist-packages/gunicorn/workers/base.py", line 122, in init_process
    self.load_wsgi()
  File "/usr/lib/python2.7/dist-packages/gunicorn/workers/base.py", line 130, in load_wsgi
    self.wsgi = self.app.wsgi()
  File "/usr/lib/python2.7/dist-packages/gunicorn/app/base.py", line 67, in wsgi
    self.callable = self.load()
  File "/usr/lib/python2.7/dist-packages/gunicorn/app/wsgiapp.py", line 65, in load
    return self.load_wsgiapp()
  File "/usr/lib/python2.7/dist-packages/gunicorn/app/wsgiapp.py", line 52, in load_wsgiapp
    return util.import_app(self.app_uri)
  File "/usr/lib/python2.7/dist-packages/gunicorn/util.py", line 366, in import_app
    __import__(module)
  File "/home/intel/xytao/hsdes.py", line 26
    def query(self, eql_json: dict, max_results: int = 1000)->dict:
                            ^
SyntaxError: invalid syntax
[2018-09-19 13:19:04 +0000] [14832] [INFO] Worker exiting (pid: 14832)
[2018-09-19 13:19:04 +0000] [14828] [INFO] Shutting down: Master
[2018-09-19 13:19:04 +0000] [14828] [INFO] Reason: Worker failed to boot.
[2018-09-19 13:19:06 +0000] [14833] [INFO] Starting gunicorn 19.4.5
[2018-09-19 13:19:06 +0000] [14833] [INFO] Listening at: http://0.0.0.0:2345 (14833)
[2018-09-19 13:19:06 +0000] [14833] [INFO] Using worker: sync
[2018-09-19 13:19:06 +0000] [14837] [INFO] Booting worker with pid: 14837
[2018-09-19 13:19:06 +0000] [14837] [ERROR] Exception in worker process:
Traceback (most recent call last):
  File "/usr/lib/python2.7/dist-packages/gunicorn/arbiter.py", line 515, in spawn_worker
    worker.init_process()
  File "/usr/lib/python2.7/dist-packages/gunicorn/workers/base.py", line 122, in init_process
    self.load_wsgi()
  File "/usr/lib/python2.7/dist-packages/gunicorn/workers/base.py", line 130, in load_wsgi
    self.wsgi = self.app.wsgi()
  File "/usr/lib/python2.7/dist-packages/gunicorn/app/base.py", line 67, in wsgi
    self.callable = self.load()
  File "/usr/lib/python2.7/dist-packages/gunicorn/app/wsgiapp.py", line 65, in load
    return self.load_wsgiapp()
  File "/usr/lib/python2.7/dist-packages/gunicorn/app/wsgiapp.py", line 52, in load_wsgiapp
    return util.import_app(self.app_uri)
  File "/usr/lib/python2.7/dist-packages/gunicorn/util.py", line 366, in import_app
    __import__(module)
  File "/home/intel/xytao/hsdes.py", line 26
    def query(self, eql_json: dict, max_results: int = 1000)->dict:
                            ^
SyntaxError: invalid syntax
Traceback (most recent call last):
  File "/usr/lib/python2.7/dist-packages/gunicorn/arbiter.py", line 515, in spawn_worker
    worker.init_process()
  File "/usr/lib/python2.7/dist-packages/gunicorn/workers/base.py", line 122, in init_process
    self.load_wsgi()
  File "/usr/lib/python2.7/dist-packages/gunicorn/workers/base.py", line 130, in load_wsgi
    self.wsgi = self.app.wsgi()
  File "/usr/lib/python2.7/dist-packages/gunicorn/app/base.py", line 67, in wsgi
    self.callable = self.load()
  File "/usr/lib/python2.7/dist-packages/gunicorn/app/wsgiapp.py", line 65, in load
    return self.load_wsgiapp()
  File "/usr/lib/python2.7/dist-packages/gunicorn/app/wsgiapp.py", line 52, in load_wsgiapp
    return util.import_app(self.app_uri)
  File "/usr/lib/python2.7/dist-packages/gunicorn/util.py", line 366, in import_app
    __import__(module)
  File "/home/intel/xytao/hsdes.py", line 26
    def query(self, eql_json: dict, max_results: int = 1000)->dict:
                            ^
SyntaxError: invalid syntax
[2018-09-19 13:19:06 +0000] [14837] [INFO] Worker exiting (pid: 14837)
[2018-09-19 13:19:06 +0000] [14833] [INFO] Shutting down: Master
[2018-09-19 13:19:06 +0000] [14833] [INFO] Reason: Worker failed to boot.
[2018-09-19 13:19:09 +0000] [14838] [INFO] Starting gunicorn 19.4.5
[2018-09-19 13:19:09 +0000] [14838] [INFO] Listening at: http://0.0.0.0:2345 (14838)
[2018-09-19 13:19:09 +0000] [14838] [INFO] Using worker: sync
[2018-09-19 13:19:09 +0000] [14842] [INFO] Booting worker with pid: 14842
[2018-09-19 13:19:09 +0000] [14842] [ERROR] Exception in worker process:
Traceback (most recent call last):
  File "/usr/lib/python2.7/dist-packages/gunicorn/arbiter.py", line 515, in spawn_worker
    worker.init_process()
  File "/usr/lib/python2.7/dist-packages/gunicorn/workers/base.py", line 122, in init_process
    self.load_wsgi()
  File "/usr/lib/python2.7/dist-packages/gunicorn/workers/base.py", line 130, in load_wsgi
    self.wsgi = self.app.wsgi()
  File "/usr/lib/python2.7/dist-packages/gunicorn/app/base.py", line 67, in wsgi
    self.callable = self.load()
  File "/usr/lib/python2.7/dist-packages/gunicorn/app/wsgiapp.py", line 65, in load
    return self.load_wsgiapp()
  File "/usr/lib/python2.7/dist-packages/gunicorn/app/wsgiapp.py", line 52, in load_wsgiapp
    return util.import_app(self.app_uri)
  File "/usr/lib/python2.7/dist-packages/gunicorn/util.py", line 366, in import_app
    __import__(module)
  File "/home/intel/xytao/hsdes.py", line 26
    def query(self, eql_json: dict, max_results: int = 1000)->dict:
                            ^
SyntaxError: invalid syntax
Traceback (most recent call last):
  File "/usr/lib/python2.7/dist-packages/gunicorn/arbiter.py", line 515, in spawn_worker
    worker.init_process()
  File "/usr/lib/python2.7/dist-packages/gunicorn/workers/base.py", line 122, in init_process
    self.load_wsgi()
  File "/usr/lib/python2.7/dist-packages/gunicorn/workers/base.py", line 130, in load_wsgi
    self.wsgi = self.app.wsgi()
  File "/usr/lib/python2.7/dist-packages/gunicorn/app/base.py", line 67, in wsgi
    self.callable = self.load()
  File "/usr/lib/python2.7/dist-packages/gunicorn/app/wsgiapp.py", line 65, in load
    return self.load_wsgiapp()
  File "/usr/lib/python2.7/dist-packages/gunicorn/app/wsgiapp.py", line 52, in load_wsgiapp
    return util.import_app(self.app_uri)
  File "/usr/lib/python2.7/dist-packages/gunicorn/util.py", line 366, in import_app
    __import__(module)
  File "/home/intel/xytao/hsdes.py", line 26
    def query(self, eql_json: dict, max_results: int = 1000)->dict:
                            ^
SyntaxError: invalid syntax
[2018-09-19 13:19:09 +0000] [14842] [INFO] Worker exiting (pid: 14842)
[2018-09-19 13:19:09 +0000] [14838] [INFO] Shutting down: Master
[2018-09-19 13:19:09 +0000] [14838] [INFO] Reason: Worker failed to boot.
Traceback (most recent call last):
  File "/home/intel/.local/bin/gunicorn", line 7, in <module>
    from gunicorn.app.wsgiapp import run
ImportError: No module named 'gunicorn'
Traceback (most recent call last):
  File "/home/intel/.local/bin/gunicorn", line 7, in <module>
    from gunicorn.app.wsgiapp import run
ImportError: No module named 'gunicorn'
Traceback (most recent call last):
  File "/home/intel/.local/bin/gunicorn", line 7, in <module>
    from gunicorn.app.wsgiapp import run
ImportError: No module named 'gunicorn'
Traceback (most recent call last):
  File "/home/intel/.local/bin/gunicorn", line 7, in <module>
    from gunicorn.app.wsgiapp import run
ImportError: No module named 'gunicorn'
Traceback (most recent call last):
  File "/home/intel/.local/bin/gunicorn", line 7, in <module>
    from gunicorn.app.wsgiapp import run
ImportError: No module named 'gunicorn'
Traceback (most recent call last):
  File "/home/intel/.local/bin/gunicorn", line 7, in <module>
    from gunicorn.app.wsgiapp import run
ImportError: No module named 'gunicorn'
Traceback (most recent call last):
  File "/home/intel/.local/bin/gunicorn", line 7, in <module>
    from gunicorn.app.wsgiapp import run
ImportError: No module named 'gunicorn'
Traceback (most recent call last):
  File "/home/intel/.local/bin/gunicorn", line 7, in <module>
    from gunicorn.app.wsgiapp import run
ImportError: No module named 'gunicorn'
[2018-09-19 13:33:32 +0800] [15655] [INFO] Starting gunicorn 19.9.0
[2018-09-19 13:33:32 +0800] [15655] [INFO] Listening at: http://0.0.0.0:2345 (15655)
[2018-09-19 13:33:32 +0800] [15655] [INFO] Using worker: sync
[2018-09-19 13:33:32 +0800] [15658] [INFO] Booting worker with pid: 15658
[2018-09-19 13:33:35 +0800] [15655] [INFO] Handling signal: term
[2018-09-19 13:33:35 +0800] [15658] [INFO] Worker exiting (pid: 15658)
[2018-09-19 13:33:36 +0800] [15655] [INFO] Shutting down: Master
[2018-09-19 13:33:37 +0800] [15664] [INFO] Starting gunicorn 19.9.0
[2018-09-19 13:33:37 +0800] [15664] [INFO] Listening at: http://0.0.0.0:2345 (15664)
[2018-09-19 13:33:37 +0800] [15664] [INFO] Using worker: sync
[2018-09-19 13:33:37 +0800] [15674] [INFO] Booting worker with pid: 15674
[2018-09-19 15:42:52 +0800] [15664] [INFO] Handling signal: term
[2018-09-19 15:42:52 +0800] [15674] [INFO] Worker exiting (pid: 15674)
[2018-09-19 15:42:52 +0800] [15664] [INFO] Shutting down: Master
[2018-09-19 15:42:53 +0800] [15845] [INFO] Starting gunicorn 19.9.0
[2018-09-19 15:42:53 +0800] [15845] [INFO] Listening at: http://0.0.0.0:2345 (15845)
[2018-09-19 15:42:53 +0800] [15845] [INFO] Using worker: sync
[2018-09-19 15:42:53 +0800] [15848] [INFO] Booting worker with pid: 15848
[2018-09-19 15:42:54 +0800] [15848] [ERROR] Exception in worker process
Traceback (most recent call last):
  File "/home/intel/.local/lib/python3.5/site-packages/gunicorn/arbiter.py", line 583, in spawn_worker
    worker.init_process()
  File "/home/intel/.local/lib/python3.5/site-packages/gunicorn/workers/base.py", line 129, in init_process
    self.load_wsgi()
  File "/home/intel/.local/lib/python3.5/site-packages/gunicorn/workers/base.py", line 138, in load_wsgi
    self.wsgi = self.app.wsgi()
  File "/home/intel/.local/lib/python3.5/site-packages/gunicorn/app/base.py", line 67, in wsgi
    self.callable = self.load()
  File "/home/intel/.local/lib/python3.5/site-packages/gunicorn/app/wsgiapp.py", line 52, in load
    return self.load_wsgiapp()
  File "/home/intel/.local/lib/python3.5/site-packages/gunicorn/app/wsgiapp.py", line 41, in load_wsgiapp
    return util.import_app(self.app_uri)
  File "/home/intel/.local/lib/python3.5/site-packages/gunicorn/util.py", line 350, in import_app
    __import__(module)
  File "/home/intel/xytao/hsdes.py", line 94, in <module>
    print(hsdes.getUserbyIdsid("taoxinyi"))
  File "/home/intel/xytao/hsdes.py", line 65, in getUserbyIdsid
    workers = json.loads(response_str)
  File "/usr/lib/python3.5/json/__init__.py", line 319, in loads
    return _default_decoder.decode(s)
  File "/usr/lib/python3.5/json/decoder.py", line 339, in decode
    obj, end = self.raw_decode(s, idx=_w(s, 0).end())
  File "/usr/lib/python3.5/json/decoder.py", line 357, in raw_decode
    raise JSONDecodeError("Expecting value", s, err.value) from None
json.decoder.JSONDecodeError: Expecting value: line 1 column 1 (char 0)
[2018-09-19 15:42:54 +0800] [15848] [INFO] Worker exiting (pid: 15848)
[2018-09-19 15:42:54 +0800] [15845] [INFO] Shutting down: Master
[2018-09-19 15:42:54 +0800] [15845] [INFO] Reason: Worker failed to boot.
[2018-09-19 15:42:55 +0800] [15852] [INFO] Starting gunicorn 19.9.0
[2018-09-19 15:42:55 +0800] [15852] [INFO] Listening at: http://0.0.0.0:2345 (15852)
[2018-09-19 15:42:55 +0800] [15852] [INFO] Using worker: sync
[2018-09-19 15:42:55 +0800] [15855] [INFO] Booting worker with pid: 15855
[2018-09-19 15:42:58 +0800] [15855] [ERROR] Exception in worker process
Traceback (most recent call last):
  File "/home/intel/.local/lib/python3.5/site-packages/gunicorn/arbiter.py", line 583, in spawn_worker
    worker.init_process()
  File "/home/intel/.local/lib/python3.5/site-packages/gunicorn/workers/base.py", line 129, in init_process
    self.load_wsgi()
  File "/home/intel/.local/lib/python3.5/site-packages/gunicorn/workers/base.py", line 138, in load_wsgi
    self.wsgi = self.app.wsgi()
  File "/home/intel/.local/lib/python3.5/site-packages/gunicorn/app/base.py", line 67, in wsgi
    self.callable = self.load()
  File "/home/intel/.local/lib/python3.5/site-packages/gunicorn/app/wsgiapp.py", line 52, in load
    return self.load_wsgiapp()
  File "/home/intel/.local/lib/python3.5/site-packages/gunicorn/app/wsgiapp.py", line 41, in load_wsgiapp
    return util.import_app(self.app_uri)
  File "/home/intel/.local/lib/python3.5/site-packages/gunicorn/util.py", line 350, in import_app
    __import__(module)
  File "/home/intel/xytao/hsdes.py", line 94, in <module>
    print(hsdes.getUserbyIdsid("taoxinyi"))
  File "/home/intel/xytao/hsdes.py", line 65, in getUserbyIdsid
    workers = json.loads(response_str)
  File "/usr/lib/python3.5/json/__init__.py", line 319, in loads
    return _default_decoder.decode(s)
  File "/usr/lib/python3.5/json/decoder.py", line 339, in decode
    obj, end = self.raw_decode(s, idx=_w(s, 0).end())
  File "/usr/lib/python3.5/json/decoder.py", line 357, in raw_decode
    raise JSONDecodeError("Expecting value", s, err.value) from None
json.decoder.JSONDecodeError: Expecting value: line 1 column 1 (char 0)
[2018-09-19 15:42:58 +0800] [15855] [INFO] Worker exiting (pid: 15855)
[2018-09-19 15:42:58 +0800] [15852] [INFO] Shutting down: Master
[2018-09-19 15:42:58 +0800] [15852] [INFO] Reason: Worker failed to boot.
[2018-09-19 15:43:00 +0800] [15859] [INFO] Starting gunicorn 19.9.0
[2018-09-19 15:43:00 +0800] [15859] [INFO] Listening at: http://0.0.0.0:2345 (15859)
[2018-09-19 15:43:00 +0800] [15859] [INFO] Using worker: sync
[2018-09-19 15:43:00 +0800] [15862] [INFO] Booting worker with pid: 15862
[2018-09-19 15:43:01 +0800] [15862] [ERROR] Exception in worker process
Traceback (most recent call last):
  File "/home/intel/.local/lib/python3.5/site-packages/gunicorn/arbiter.py", line 583, in spawn_worker
    worker.init_process()
  File "/home/intel/.local/lib/python3.5/site-packages/gunicorn/workers/base.py", line 129, in init_process
    self.load_wsgi()
  File "/home/intel/.local/lib/python3.5/site-packages/gunicorn/workers/base.py", line 138, in load_wsgi
    self.wsgi = self.app.wsgi()
  File "/home/intel/.local/lib/python3.5/site-packages/gunicorn/app/base.py", line 67, in wsgi
    self.callable = self.load()
  File "/home/intel/.local/lib/python3.5/site-packages/gunicorn/app/wsgiapp.py", line 52, in load
    return self.load_wsgiapp()
  File "/home/intel/.local/lib/python3.5/site-packages/gunicorn/app/wsgiapp.py", line 41, in load_wsgiapp
    return util.import_app(self.app_uri)
  File "/home/intel/.local/lib/python3.5/site-packages/gunicorn/util.py", line 350, in import_app
    __import__(module)
  File "/home/intel/xytao/hsdes.py", line 94, in <module>
    print(hsdes.getUserbyIdsid("taoxinyi"))
  File "/home/intel/xytao/hsdes.py", line 65, in getUserbyIdsid
    workers = json.loads(response_str)
  File "/usr/lib/python3.5/json/__init__.py", line 319, in loads
    return _default_decoder.decode(s)
  File "/usr/lib/python3.5/json/decoder.py", line 339, in decode
    obj, end = self.raw_decode(s, idx=_w(s, 0).end())
  File "/usr/lib/python3.5/json/decoder.py", line 357, in raw_decode
    raise JSONDecodeError("Expecting value", s, err.value) from None
json.decoder.JSONDecodeError: Expecting value: line 1 column 1 (char 0)
[2018-09-19 15:43:01 +0800] [15862] [INFO] Worker exiting (pid: 15862)
[2018-09-19 15:43:01 +0800] [15859] [INFO] Shutting down: Master
[2018-09-19 15:43:01 +0800] [15859] [INFO] Reason: Worker failed to boot.
[2018-09-19 15:43:02 +0800] [15866] [INFO] Starting gunicorn 19.9.0
[2018-09-19 15:43:02 +0800] [15866] [INFO] Listening at: http://0.0.0.0:2345 (15866)
[2018-09-19 15:43:02 +0800] [15866] [INFO] Using worker: sync
[2018-09-19 15:43:02 +0800] [15869] [INFO] Booting worker with pid: 15869
[2018-09-19 15:43:05 +0800] [15869] [ERROR] Exception in worker process
Traceback (most recent call last):
  File "/home/intel/.local/lib/python3.5/site-packages/gunicorn/arbiter.py", line 583, in spawn_worker
    worker.init_process()
  File "/home/intel/.local/lib/python3.5/site-packages/gunicorn/workers/base.py", line 129, in init_process
    self.load_wsgi()
  File "/home/intel/.local/lib/python3.5/site-packages/gunicorn/workers/base.py", line 138, in load_wsgi
    self.wsgi = self.app.wsgi()
  File "/home/intel/.local/lib/python3.5/site-packages/gunicorn/app/base.py", line 67, in wsgi
    self.callable = self.load()
  File "/home/intel/.local/lib/python3.5/site-packages/gunicorn/app/wsgiapp.py", line 52, in load
    return self.load_wsgiapp()
  File "/home/intel/.local/lib/python3.5/site-packages/gunicorn/app/wsgiapp.py", line 41, in load_wsgiapp
    return util.import_app(self.app_uri)
  File "/home/intel/.local/lib/python3.5/site-packages/gunicorn/util.py", line 350, in import_app
    __import__(module)
  File "/home/intel/xytao/hsdes.py", line 94, in <module>
    print(hsdes.getUserbyIdsid("taoxinyi"))
  File "/home/intel/xytao/hsdes.py", line 65, in getUserbyIdsid
    workers = json.loads(response_str)
  File "/usr/lib/python3.5/json/__init__.py", line 319, in loads
    return _default_decoder.decode(s)
  File "/usr/lib/python3.5/json/decoder.py", line 339, in decode
    obj, end = self.raw_decode(s, idx=_w(s, 0).end())
  File "/usr/lib/python3.5/json/decoder.py", line 357, in raw_decode
    raise JSONDecodeError("Expecting value", s, err.value) from None
json.decoder.JSONDecodeError: Expecting value: line 1 column 1 (char 0)
[2018-09-19 15:43:05 +0800] [15869] [INFO] Worker exiting (pid: 15869)
[2018-09-19 15:43:06 +0800] [15866] [INFO] Shutting down: Master
[2018-09-19 15:43:06 +0800] [15866] [INFO] Reason: Worker failed to boot.
[2018-09-19 15:43:07 +0800] [15873] [INFO] Starting gunicorn 19.9.0
[2018-09-19 15:43:07 +0800] [15873] [INFO] Listening at: http://0.0.0.0:2345 (15873)
[2018-09-19 15:43:07 +0800] [15873] [INFO] Using worker: sync
[2018-09-19 15:43:07 +0800] [15876] [INFO] Booting worker with pid: 15876
[2018-09-19 15:43:08 +0800] [15876] [ERROR] Exception in worker process
Traceback (most recent call last):
  File "/home/intel/.local/lib/python3.5/site-packages/gunicorn/arbiter.py", line 583, in spawn_worker
    worker.init_process()
  File "/home/intel/.local/lib/python3.5/site-packages/gunicorn/workers/base.py", line 129, in init_process
    self.load_wsgi()
  File "/home/intel/.local/lib/python3.5/site-packages/gunicorn/workers/base.py", line 138, in load_wsgi
    self.wsgi = self.app.wsgi()
  File "/home/intel/.local/lib/python3.5/site-packages/gunicorn/app/base.py", line 67, in wsgi
    self.callable = self.load()
  File "/home/intel/.local/lib/python3.5/site-packages/gunicorn/app/wsgiapp.py", line 52, in load
    return self.load_wsgiapp()
  File "/home/intel/.local/lib/python3.5/site-packages/gunicorn/app/wsgiapp.py", line 41, in load_wsgiapp
    return util.import_app(self.app_uri)
  File "/home/intel/.local/lib/python3.5/site-packages/gunicorn/util.py", line 350, in import_app
    __import__(module)
  File "/home/intel/xytao/hsdes.py", line 94, in <module>
    print(hsdes.getUserbyIdsid("taoxinyi"))
  File "/home/intel/xytao/hsdes.py", line 65, in getUserbyIdsid
    workers = json.loads(response_str)
  File "/usr/lib/python3.5/json/__init__.py", line 319, in loads
    return _default_decoder.decode(s)
  File "/usr/lib/python3.5/json/decoder.py", line 339, in decode
    obj, end = self.raw_decode(s, idx=_w(s, 0).end())
  File "/usr/lib/python3.5/json/decoder.py", line 357, in raw_decode
    raise JSONDecodeError("Expecting value", s, err.value) from None
json.decoder.JSONDecodeError: Expecting value: line 1 column 1 (char 0)
[2018-09-19 15:43:08 +0800] [15876] [INFO] Worker exiting (pid: 15876)
[2018-09-19 15:43:08 +0800] [15873] [INFO] Shutting down: Master
[2018-09-19 15:43:08 +0800] [15873] [INFO] Reason: Worker failed to boot.
[2018-09-19 15:43:10 +0800] [15880] [INFO] Starting gunicorn 19.9.0
[2018-09-19 15:43:10 +0800] [15880] [INFO] Listening at: http://0.0.0.0:2345 (15880)
[2018-09-19 15:43:10 +0800] [15880] [INFO] Using worker: sync
[2018-09-19 15:43:10 +0800] [15883] [INFO] Booting worker with pid: 15883
[2018-09-19 15:43:13 +0800] [15883] [ERROR] Exception in worker process
Traceback (most recent call last):
  File "/home/intel/.local/lib/python3.5/site-packages/gunicorn/arbiter.py", line 583, in spawn_worker
    worker.init_process()
  File "/home/intel/.local/lib/python3.5/site-packages/gunicorn/workers/base.py", line 129, in init_process
    self.load_wsgi()
  File "/home/intel/.local/lib/python3.5/site-packages/gunicorn/workers/base.py", line 138, in load_wsgi
    self.wsgi = self.app.wsgi()
  File "/home/intel/.local/lib/python3.5/site-packages/gunicorn/app/base.py", line 67, in wsgi
    self.callable = self.load()
  File "/home/intel/.local/lib/python3.5/site-packages/gunicorn/app/wsgiapp.py", line 52, in load
    return self.load_wsgiapp()
  File "/home/intel/.local/lib/python3.5/site-packages/gunicorn/app/wsgiapp.py", line 41, in load_wsgiapp
    return util.import_app(self.app_uri)
  File "/home/intel/.local/lib/python3.5/site-packages/gunicorn/util.py", line 350, in import_app
    __import__(module)
  File "/home/intel/xytao/hsdes.py", line 94, in <module>
    print(hsdes.getUserbyIdsid("taoxinyi"))
  File "/home/intel/xytao/hsdes.py", line 65, in getUserbyIdsid
    workers = json.loads(response_str)
  File "/usr/lib/python3.5/json/__init__.py", line 319, in loads
    return _default_decoder.decode(s)
  File "/usr/lib/python3.5/json/decoder.py", line 339, in decode
    obj, end = self.raw_decode(s, idx=_w(s, 0).end())
  File "/usr/lib/python3.5/json/decoder.py", line 357, in raw_decode
    raise JSONDecodeError("Expecting value", s, err.value) from None
json.decoder.JSONDecodeError: Expecting value: line 1 column 1 (char 0)
[2018-09-19 15:43:13 +0800] [15883] [INFO] Worker exiting (pid: 15883)
[2018-09-19 15:43:13 +0800] [15880] [INFO] Shutting down: Master
[2018-09-19 15:43:13 +0800] [15880] [INFO] Reason: Worker failed to boot.
[2018-09-19 15:43:13 +0800] [15887] [INFO] Starting gunicorn 19.9.0
[2018-09-19 15:43:13 +0800] [15887] [INFO] Listening at: http://0.0.0.0:2345 (15887)
[2018-09-19 15:43:13 +0800] [15887] [INFO] Using worker: sync
[2018-09-19 15:43:13 +0800] [15891] [INFO] Booting worker with pid: 15891
[2018-09-19 15:43:16 +0800] [15891] [ERROR] Exception in worker process
Traceback (most recent call last):
  File "/home/intel/.local/lib/python3.5/site-packages/gunicorn/arbiter.py", line 583, in spawn_worker
    worker.init_process()
  File "/home/intel/.local/lib/python3.5/site-packages/gunicorn/workers/base.py", line 129, in init_process
    self.load_wsgi()
  File "/home/intel/.local/lib/python3.5/site-packages/gunicorn/workers/base.py", line 138, in load_wsgi
    self.wsgi = self.app.wsgi()
  File "/home/intel/.local/lib/python3.5/site-packages/gunicorn/app/base.py", line 67, in wsgi
    self.callable = self.load()
  File "/home/intel/.local/lib/python3.5/site-packages/gunicorn/app/wsgiapp.py", line 52, in load
    return self.load_wsgiapp()
  File "/home/intel/.local/lib/python3.5/site-packages/gunicorn/app/wsgiapp.py", line 41, in load_wsgiapp
    return util.import_app(self.app_uri)
  File "/home/intel/.local/lib/python3.5/site-packages/gunicorn/util.py", line 350, in import_app
    __import__(module)
  File "/home/intel/xytao/hsdes.py", line 94, in <module>
    print(hsdes.getUserbyIdsid("taoxinyi"))
  File "/home/intel/xytao/hsdes.py", line 65, in getUserbyIdsid
    workers = json.loads(response_str)
  File "/usr/lib/python3.5/json/__init__.py", line 319, in loads
    return _default_decoder.decode(s)
  File "/usr/lib/python3.5/json/decoder.py", line 339, in decode
    obj, end = self.raw_decode(s, idx=_w(s, 0).end())
  File "/usr/lib/python3.5/json/decoder.py", line 357, in raw_decode
    raise JSONDecodeError("Expecting value", s, err.value) from None
json.decoder.JSONDecodeError: Expecting value: line 1 column 1 (char 0)
[2018-09-19 15:43:16 +0800] [15891] [INFO] Worker exiting (pid: 15891)
[2018-09-19 15:43:17 +0800] [15887] [INFO] Shutting down: Master
[2018-09-19 15:43:17 +0800] [15887] [INFO] Reason: Worker failed to boot.
[2018-09-19 15:43:18 +0800] [15901] [INFO] Starting gunicorn 19.9.0
[2018-09-19 15:43:18 +0800] [15901] [INFO] Listening at: http://0.0.0.0:2345 (15901)
[2018-09-19 15:43:18 +0800] [15901] [INFO] Using worker: sync
[2018-09-19 15:43:18 +0800] [15904] [INFO] Booting worker with pid: 15904
[2018-09-19 15:43:21 +0800] [15904] [ERROR] Exception in worker process
Traceback (most recent call last):
  File "/home/intel/.local/lib/python3.5/site-packages/gunicorn/arbiter.py", line 583, in spawn_worker
    worker.init_process()
  File "/home/intel/.local/lib/python3.5/site-packages/gunicorn/workers/base.py", line 129, in init_process
    self.load_wsgi()
  File "/home/intel/.local/lib/python3.5/site-packages/gunicorn/workers/base.py", line 138, in load_wsgi
    self.wsgi = self.app.wsgi()
  File "/home/intel/.local/lib/python3.5/site-packages/gunicorn/app/base.py", line 67, in wsgi
    self.callable = self.load()
  File "/home/intel/.local/lib/python3.5/site-packages/gunicorn/app/wsgiapp.py", line 52, in load
    return self.load_wsgiapp()
  File "/home/intel/.local/lib/python3.5/site-packages/gunicorn/app/wsgiapp.py", line 41, in load_wsgiapp
    return util.import_app(self.app_uri)
  File "/home/intel/.local/lib/python3.5/site-packages/gunicorn/util.py", line 350, in import_app
    __import__(module)
  File "/home/intel/xytao/hsdes.py", line 94, in <module>
    print(hsdes.getUserbyIdsid("taoxinyi"))
  File "/home/intel/xytao/hsdes.py", line 65, in getUserbyIdsid
    workers = json.loads(response_str)
  File "/usr/lib/python3.5/json/__init__.py", line 319, in loads
    return _default_decoder.decode(s)
  File "/usr/lib/python3.5/json/decoder.py", line 339, in decode
    obj, end = self.raw_decode(s, idx=_w(s, 0).end())
  File "/usr/lib/python3.5/json/decoder.py", line 357, in raw_decode
    raise JSONDecodeError("Expecting value", s, err.value) from None
json.decoder.JSONDecodeError: Expecting value: line 1 column 1 (char 0)
[2018-09-19 15:43:21 +0800] [15904] [INFO] Worker exiting (pid: 15904)
[2018-09-19 15:43:21 +0800] [15901] [INFO] Shutting down: Master
[2018-09-19 15:43:21 +0800] [15901] [INFO] Reason: Worker failed to boot.
[2018-09-19 15:43:23 +0800] [15908] [INFO] Starting gunicorn 19.9.0
[2018-09-19 15:43:23 +0800] [15908] [INFO] Listening at: http://0.0.0.0:2345 (15908)
[2018-09-19 15:43:23 +0800] [15908] [INFO] Using worker: sync
[2018-09-19 15:43:23 +0800] [15911] [INFO] Booting worker with pid: 15911
[2018-09-19 15:43:26 +0800] [15911] [ERROR] Exception in worker process
Traceback (most recent call last):
  File "/home/intel/.local/lib/python3.5/site-packages/gunicorn/arbiter.py", line 583, in spawn_worker
    worker.init_process()
  File "/home/intel/.local/lib/python3.5/site-packages/gunicorn/workers/base.py", line 129, in init_process
    self.load_wsgi()
  File "/home/intel/.local/lib/python3.5/site-packages/gunicorn/workers/base.py", line 138, in load_wsgi
    self.wsgi = self.app.wsgi()
  File "/home/intel/.local/lib/python3.5/site-packages/gunicorn/app/base.py", line 67, in wsgi
    self.callable = self.load()
  File "/home/intel/.local/lib/python3.5/site-packages/gunicorn/app/wsgiapp.py", line 52, in load
    return self.load_wsgiapp()
  File "/home/intel/.local/lib/python3.5/site-packages/gunicorn/app/wsgiapp.py", line 41, in load_wsgiapp
    return util.import_app(self.app_uri)
  File "/home/intel/.local/lib/python3.5/site-packages/gunicorn/util.py", line 350, in import_app
    __import__(module)
  File "/home/intel/xytao/hsdes.py", line 94, in <module>
    print(hsdes.getUserbyIdsid("taoxinyi"))
  File "/home/intel/xytao/hsdes.py", line 65, in getUserbyIdsid
    workers = json.loads(response_str)
  File "/usr/lib/python3.5/json/__init__.py", line 319, in loads
    return _default_decoder.decode(s)
  File "/usr/lib/python3.5/json/decoder.py", line 339, in decode
    obj, end = self.raw_decode(s, idx=_w(s, 0).end())
  File "/usr/lib/python3.5/json/decoder.py", line 357, in raw_decode
    raise JSONDecodeError("Expecting value", s, err.value) from None
json.decoder.JSONDecodeError: Expecting value: line 1 column 1 (char 0)
[2018-09-19 15:43:26 +0800] [15911] [INFO] Worker exiting (pid: 15911)
[2018-09-19 15:43:26 +0800] [15908] [INFO] Shutting down: Master
[2018-09-19 15:43:26 +0800] [15908] [INFO] Reason: Worker failed to boot.
[2018-09-19 15:43:27 +0800] [15926] [INFO] Starting gunicorn 19.9.0
[2018-09-19 15:43:27 +0800] [15926] [INFO] Listening at: http://0.0.0.0:2345 (15926)
[2018-09-19 15:43:27 +0800] [15926] [INFO] Using worker: sync
[2018-09-19 15:43:27 +0800] [15929] [INFO] Booting worker with pid: 15929
[2018-09-19 15:43:30 +0800] [15929] [ERROR] Exception in worker process
Traceback (most recent call last):
  File "/home/intel/.local/lib/python3.5/site-packages/gunicorn/arbiter.py", line 583, in spawn_worker
    worker.init_process()
  File "/home/intel/.local/lib/python3.5/site-packages/gunicorn/workers/base.py", line 129, in init_process
    self.load_wsgi()
  File "/home/intel/.local/lib/python3.5/site-packages/gunicorn/workers/base.py", line 138, in load_wsgi
    self.wsgi = self.app.wsgi()
  File "/home/intel/.local/lib/python3.5/site-packages/gunicorn/app/base.py", line 67, in wsgi
    self.callable = self.load()
  File "/home/intel/.local/lib/python3.5/site-packages/gunicorn/app/wsgiapp.py", line 52, in load
    return self.load_wsgiapp()
  File "/home/intel/.local/lib/python3.5/site-packages/gunicorn/app/wsgiapp.py", line 41, in load_wsgiapp
    return util.import_app(self.app_uri)
  File "/home/intel/.local/lib/python3.5/site-packages/gunicorn/util.py", line 350, in import_app
    __import__(module)
  File "/home/intel/xytao/hsdes.py", line 94, in <module>
    print(hsdes.getUserbyIdsid("taoxinyi"))
  File "/home/intel/xytao/hsdes.py", line 65, in getUserbyIdsid
    workers = json.loads(response_str)
  File "/usr/lib/python3.5/json/__init__.py", line 319, in loads
    return _default_decoder.decode(s)
  File "/usr/lib/python3.5/json/decoder.py", line 339, in decode
    obj, end = self.raw_decode(s, idx=_w(s, 0).end())
  File "/usr/lib/python3.5/json/decoder.py", line 357, in raw_decode
    raise JSONDecodeError("Expecting value", s, err.value) from None
json.decoder.JSONDecodeError: Expecting value: line 1 column 1 (char 0)
[2018-09-19 15:43:30 +0800] [15929] [INFO] Worker exiting (pid: 15929)
[2018-09-19 15:43:30 +0800] [15926] [INFO] Shutting down: Master
[2018-09-19 15:43:30 +0800] [15926] [INFO] Reason: Worker failed to boot.
[2018-09-19 15:43:32 +0800] [15933] [INFO] Starting gunicorn 19.9.0
[2018-09-19 15:43:32 +0800] [15933] [INFO] Listening at: http://0.0.0.0:2345 (15933)
[2018-09-19 15:43:32 +0800] [15933] [INFO] Using worker: sync
[2018-09-19 15:43:32 +0800] [15936] [INFO] Booting worker with pid: 15936
[2018-09-19 15:43:35 +0800] [15936] [ERROR] Exception in worker process
Traceback (most recent call last):
  File "/home/intel/.local/lib/python3.5/site-packages/gunicorn/arbiter.py", line 583, in spawn_worker
    worker.init_process()
  File "/home/intel/.local/lib/python3.5/site-packages/gunicorn/workers/base.py", line 129, in init_process
    self.load_wsgi()
  File "/home/intel/.local/lib/python3.5/site-packages/gunicorn/workers/base.py", line 138, in load_wsgi
    self.wsgi = self.app.wsgi()
  File "/home/intel/.local/lib/python3.5/site-packages/gunicorn/app/base.py", line 67, in wsgi
    self.callable = self.load()
  File "/home/intel/.local/lib/python3.5/site-packages/gunicorn/app/wsgiapp.py", line 52, in load
    return self.load_wsgiapp()
  File "/home/intel/.local/lib/python3.5/site-packages/gunicorn/app/wsgiapp.py", line 41, in load_wsgiapp
    return util.import_app(self.app_uri)
  File "/home/intel/.local/lib/python3.5/site-packages/gunicorn/util.py", line 350, in import_app
    __import__(module)
  File "/home/intel/xytao/hsdes.py", line 94, in <module>
    print(hsdes.getUserbyIdsid("taoxinyi"))
  File "/home/intel/xytao/hsdes.py", line 65, in getUserbyIdsid
    workers = json.loads(response_str)
  File "/usr/lib/python3.5/json/__init__.py", line 319, in loads
    return _default_decoder.decode(s)
  File "/usr/lib/python3.5/json/decoder.py", line 339, in decode
    obj, end = self.raw_decode(s, idx=_w(s, 0).end())
  File "/usr/lib/python3.5/json/decoder.py", line 357, in raw_decode
    raise JSONDecodeError("Expecting value", s, err.value) from None
json.decoder.JSONDecodeError: Expecting value: line 1 column 1 (char 0)
[2018-09-19 15:43:35 +0800] [15936] [INFO] Worker exiting (pid: 15936)
[2018-09-19 15:43:35 +0800] [15933] [INFO] Shutting down: Master
[2018-09-19 15:43:35 +0800] [15933] [INFO] Reason: Worker failed to boot.
[2018-09-19 15:43:36 +0800] [15940] [INFO] Starting gunicorn 19.9.0
[2018-09-19 15:43:36 +0800] [15940] [INFO] Listening at: http://0.0.0.0:2345 (15940)
[2018-09-19 15:43:36 +0800] [15940] [INFO] Using worker: sync
[2018-09-19 15:43:36 +0800] [15943] [INFO] Booting worker with pid: 15943
[2018-09-19 15:43:39 +0800] [15943] [ERROR] Exception in worker process
Traceback (most recent call last):
  File "/home/intel/.local/lib/python3.5/site-packages/gunicorn/arbiter.py", line 583, in spawn_worker
    worker.init_process()
  File "/home/intel/.local/lib/python3.5/site-packages/gunicorn/workers/base.py", line 129, in init_process
    self.load_wsgi()
  File "/home/intel/.local/lib/python3.5/site-packages/gunicorn/workers/base.py", line 138, in load_wsgi
    self.wsgi = self.app.wsgi()
  File "/home/intel/.local/lib/python3.5/site-packages/gunicorn/app/base.py", line 67, in wsgi
    self.callable = self.load()
  File "/home/intel/.local/lib/python3.5/site-packages/gunicorn/app/wsgiapp.py", line 52, in load
    return self.load_wsgiapp()
  File "/home/intel/.local/lib/python3.5/site-packages/gunicorn/app/wsgiapp.py", line 41, in load_wsgiapp
    return util.import_app(self.app_uri)
  File "/home/intel/.local/lib/python3.5/site-packages/gunicorn/util.py", line 350, in import_app
    __import__(module)
  File "/home/intel/xytao/hsdes.py", line 94, in <module>
    print(hsdes.getUserbyIdsid("taoxinyi"))
  File "/home/intel/xytao/hsdes.py", line 65, in getUserbyIdsid
    workers = json.loads(response_str)
  File "/usr/lib/python3.5/json/__init__.py", line 319, in loads
    return _default_decoder.decode(s)
  File "/usr/lib/python3.5/json/decoder.py", line 339, in decode
    obj, end = self.raw_decode(s, idx=_w(s, 0).end())
  File "/usr/lib/python3.5/json/decoder.py", line 357, in raw_decode
    raise JSONDecodeError("Expecting value", s, err.value) from None
json.decoder.JSONDecodeError: Expecting value: line 1 column 1 (char 0)
[2018-09-19 15:43:40 +0800] [15943] [INFO] Worker exiting (pid: 15943)
[2018-09-19 15:43:40 +0800] [15940] [INFO] Shutting down: Master
[2018-09-19 15:43:40 +0800] [15940] [INFO] Reason: Worker failed to boot.
[2018-09-19 15:43:41 +0800] [15947] [INFO] Starting gunicorn 19.9.0
[2018-09-19 15:43:41 +0800] [15947] [INFO] Listening at: http://0.0.0.0:2345 (15947)
[2018-09-19 15:43:41 +0800] [15947] [INFO] Using worker: sync
[2018-09-19 15:43:41 +0800] [15950] [INFO] Booting worker with pid: 15950
[2018-09-19 15:43:44 +0800] [15950] [ERROR] Exception in worker process
Traceback (most recent call last):
  File "/home/intel/.local/lib/python3.5/site-packages/gunicorn/arbiter.py", line 583, in spawn_worker
    worker.init_process()
  File "/home/intel/.local/lib/python3.5/site-packages/gunicorn/workers/base.py", line 129, in init_process
    self.load_wsgi()
  File "/home/intel/.local/lib/python3.5/site-packages/gunicorn/workers/base.py", line 138, in load_wsgi
    self.wsgi = self.app.wsgi()
  File "/home/intel/.local/lib/python3.5/site-packages/gunicorn/app/base.py", line 67, in wsgi
    self.callable = self.load()
  File "/home/intel/.local/lib/python3.5/site-packages/gunicorn/app/wsgiapp.py", line 52, in load
    return self.load_wsgiapp()
  File "/home/intel/.local/lib/python3.5/site-packages/gunicorn/app/wsgiapp.py", line 41, in load_wsgiapp
    return util.import_app(self.app_uri)
  File "/home/intel/.local/lib/python3.5/site-packages/gunicorn/util.py", line 350, in import_app
    __import__(module)
  File "/home/intel/xytao/hsdes.py", line 94, in <module>
    print(hsdes.getUserbyIdsid("taoxinyi"))
  File "/home/intel/xytao/hsdes.py", line 65, in getUserbyIdsid
    workers = json.loads(response_str)
  File "/usr/lib/python3.5/json/__init__.py", line 319, in loads
    return _default_decoder.decode(s)
  File "/usr/lib/python3.5/json/decoder.py", line 339, in decode
    obj, end = self.raw_decode(s, idx=_w(s, 0).end())
  File "/usr/lib/python3.5/json/decoder.py", line 357, in raw_decode
    raise JSONDecodeError("Expecting value", s, err.value) from None
json.decoder.JSONDecodeError: Expecting value: line 1 column 1 (char 0)
[2018-09-19 15:43:44 +0800] [15950] [INFO] Worker exiting (pid: 15950)
[2018-09-19 15:43:44 +0800] [15947] [INFO] Shutting down: Master
[2018-09-19 15:43:44 +0800] [15947] [INFO] Reason: Worker failed to boot.
[2018-09-19 15:43:46 +0800] [15954] [INFO] Starting gunicorn 19.9.0
[2018-09-19 15:43:46 +0800] [15954] [INFO] Listening at: http://0.0.0.0:2345 (15954)
[2018-09-19 15:43:46 +0800] [15954] [INFO] Using worker: sync
[2018-09-19 15:43:46 +0800] [15957] [INFO] Booting worker with pid: 15957
[2018-09-19 15:43:49 +0800] [15957] [ERROR] Exception in worker process
Traceback (most recent call last):
  File "/home/intel/.local/lib/python3.5/site-packages/gunicorn/arbiter.py", line 583, in spawn_worker
    worker.init_process()
  File "/home/intel/.local/lib/python3.5/site-packages/gunicorn/workers/base.py", line 129, in init_process
    self.load_wsgi()
  File "/home/intel/.local/lib/python3.5/site-packages/gunicorn/workers/base.py", line 138, in load_wsgi
    self.wsgi = self.app.wsgi()
  File "/home/intel/.local/lib/python3.5/site-packages/gunicorn/app/base.py", line 67, in wsgi
    self.callable = self.load()
  File "/home/intel/.local/lib/python3.5/site-packages/gunicorn/app/wsgiapp.py", line 52, in load
    return self.load_wsgiapp()
  File "/home/intel/.local/lib/python3.5/site-packages/gunicorn/app/wsgiapp.py", line 41, in load_wsgiapp
    return util.import_app(self.app_uri)
  File "/home/intel/.local/lib/python3.5/site-packages/gunicorn/util.py", line 350, in import_app
    __import__(module)
  File "/home/intel/xytao/hsdes.py", line 94, in <module>
    print(hsdes.getUserbyIdsid("taoxinyi"))
  File "/home/intel/xytao/hsdes.py", line 65, in getUserbyIdsid
    workers = json.loads(response_str)
  File "/usr/lib/python3.5/json/__init__.py", line 319, in loads
    return _default_decoder.decode(s)
  File "/usr/lib/python3.5/json/decoder.py", line 339, in decode
    obj, end = self.raw_decode(s, idx=_w(s, 0).end())
  File "/usr/lib/python3.5/json/decoder.py", line 357, in raw_decode
    raise JSONDecodeError("Expecting value", s, err.value) from None
json.decoder.JSONDecodeError: Expecting value: line 1 column 1 (char 0)
[2018-09-19 15:43:49 +0800] [15957] [INFO] Worker exiting (pid: 15957)
[2018-09-19 15:43:49 +0800] [15954] [INFO] Shutting down: Master
[2018-09-19 15:43:49 +0800] [15954] [INFO] Reason: Worker failed to boot.
[2018-09-19 15:43:50 +0800] [15961] [INFO] Starting gunicorn 19.9.0
[2018-09-19 15:43:50 +0800] [15961] [INFO] Listening at: http://0.0.0.0:2345 (15961)
[2018-09-19 15:43:50 +0800] [15961] [INFO] Using worker: sync
[2018-09-19 15:43:50 +0800] [15964] [INFO] Booting worker with pid: 15964
[2018-09-19 15:43:51 +0800] [15964] [ERROR] Exception in worker process
Traceback (most recent call last):
  File "/home/intel/.local/lib/python3.5/site-packages/gunicorn/arbiter.py", line 583, in spawn_worker
    worker.init_process()
  File "/home/intel/.local/lib/python3.5/site-packages/gunicorn/workers/base.py", line 129, in init_process
    self.load_wsgi()
  File "/home/intel/.local/lib/python3.5/site-packages/gunicorn/workers/base.py", line 138, in load_wsgi
    self.wsgi = self.app.wsgi()
  File "/home/intel/.local/lib/python3.5/site-packages/gunicorn/app/base.py", line 67, in wsgi
    self.callable = self.load()
  File "/home/intel/.local/lib/python3.5/site-packages/gunicorn/app/wsgiapp.py", line 52, in load
    return self.load_wsgiapp()
  File "/home/intel/.local/lib/python3.5/site-packages/gunicorn/app/wsgiapp.py", line 41, in load_wsgiapp
    return util.import_app(self.app_uri)
  File "/home/intel/.local/lib/python3.5/site-packages/gunicorn/util.py", line 350, in import_app
    __import__(module)
  File "/home/intel/xytao/hsdes.py", line 94, in <module>
    print(hsdes.getUserbyIdsid("taoxinyi"))
  File "/home/intel/xytao/hsdes.py", line 65, in getUserbyIdsid
    workers = json.loads(response_str)
  File "/usr/lib/python3.5/json/__init__.py", line 319, in loads
    return _default_decoder.decode(s)
  File "/usr/lib/python3.5/json/decoder.py", line 339, in decode
    obj, end = self.raw_decode(s, idx=_w(s, 0).end())
  File "/usr/lib/python3.5/json/decoder.py", line 357, in raw_decode
    raise JSONDecodeError("Expecting value", s, err.value) from None
json.decoder.JSONDecodeError: Expecting value: line 1 column 1 (char 0)
[2018-09-19 15:43:51 +0800] [15964] [INFO] Worker exiting (pid: 15964)
[2018-09-19 15:43:52 +0800] [15961] [INFO] Shutting down: Master
[2018-09-19 15:43:52 +0800] [15961] [INFO] Reason: Worker failed to boot.
[2018-09-19 15:43:53 +0800] [15968] [INFO] Starting gunicorn 19.9.0
[2018-09-19 15:43:53 +0800] [15968] [INFO] Listening at: http://0.0.0.0:2345 (15968)
[2018-09-19 15:43:53 +0800] [15968] [INFO] Using worker: sync
[2018-09-19 15:43:53 +0800] [15971] [INFO] Booting worker with pid: 15971
[2018-09-19 15:43:56 +0800] [15971] [ERROR] Exception in worker process
Traceback (most recent call last):
  File "/home/intel/.local/lib/python3.5/site-packages/gunicorn/arbiter.py", line 583, in spawn_worker
    worker.init_process()
  File "/home/intel/.local/lib/python3.5/site-packages/gunicorn/workers/base.py", line 129, in init_process
    self.load_wsgi()
  File "/home/intel/.local/lib/python3.5/site-packages/gunicorn/workers/base.py", line 138, in load_wsgi
    self.wsgi = self.app.wsgi()
  File "/home/intel/.local/lib/python3.5/site-packages/gunicorn/app/base.py", line 67, in wsgi
    self.callable = self.load()
  File "/home/intel/.local/lib/python3.5/site-packages/gunicorn/app/wsgiapp.py", line 52, in load
    return self.load_wsgiapp()
  File "/home/intel/.local/lib/python3.5/site-packages/gunicorn/app/wsgiapp.py", line 41, in load_wsgiapp
    return util.import_app(self.app_uri)
  File "/home/intel/.local/lib/python3.5/site-packages/gunicorn/util.py", line 350, in import_app
    __import__(module)
  File "/home/intel/xytao/hsdes.py", line 94, in <module>
    print(hsdes.getUserbyIdsid("taoxinyi"))
  File "/home/intel/xytao/hsdes.py", line 65, in getUserbyIdsid
    workers = json.loads(response_str)
  File "/usr/lib/python3.5/json/__init__.py", line 319, in loads
    return _default_decoder.decode(s)
  File "/usr/lib/python3.5/json/decoder.py", line 339, in decode
    obj, end = self.raw_decode(s, idx=_w(s, 0).end())
  File "/usr/lib/python3.5/json/decoder.py", line 357, in raw_decode
    raise JSONDecodeError("Expecting value", s, err.value) from None
json.decoder.JSONDecodeError: Expecting value: line 1 column 1 (char 0)
[2018-09-19 15:43:56 +0800] [15971] [INFO] Worker exiting (pid: 15971)
[2018-09-19 15:43:56 +0800] [15968] [INFO] Shutting down: Master
[2018-09-19 15:43:56 +0800] [15968] [INFO] Reason: Worker failed to boot.
[2018-09-19 15:43:58 +0800] [15975] [INFO] Starting gunicorn 19.9.0
[2018-09-19 15:43:58 +0800] [15975] [INFO] Listening at: http://0.0.0.0:2345 (15975)
[2018-09-19 15:43:58 +0800] [15975] [INFO] Using worker: sync
[2018-09-19 15:43:58 +0800] [15978] [INFO] Booting worker with pid: 15978
[2018-09-19 15:44:09 +0800] [15975] [INFO] Handling signal: term
[2018-09-19 15:44:09 +0800] [15978] [INFO] Worker exiting (pid: 15978)
[2018-09-19 15:44:09 +0800] [15975] [INFO] Shutting down: Master
[2018-09-19 15:44:09 +0800] [15984] [INFO] Starting gunicorn 19.9.0
[2018-09-19 15:44:09 +0800] [15984] [INFO] Listening at: http://0.0.0.0:2345 (15984)
[2018-09-19 15:44:09 +0800] [15984] [INFO] Using worker: sync
[2018-09-19 15:44:09 +0800] [15987] [INFO] Booting worker with pid: 15987
[2018-09-19 15:46:51 +0800] [15984] [INFO] Handling signal: term
[2018-09-19 15:46:51 +0800] [15987] [INFO] Worker exiting (pid: 15987)
[2018-09-19 15:46:51 +0800] [15984] [INFO] Shutting down: Master
[2018-09-19 15:46:51 +0800] [16000] [INFO] Starting gunicorn 19.9.0
[2018-09-19 15:46:51 +0800] [16000] [INFO] Listening at: http://0.0.0.0:2345 (16000)
[2018-09-19 15:46:51 +0800] [16000] [INFO] Using worker: sync
[2018-09-19 15:46:51 +0800] [16003] [INFO] Booting worker with pid: 16003
[2018-09-19 15:46:51 +0800] [16003] [ERROR] Exception in worker process
Traceback (most recent call last):
  File "/home/intel/.local/lib/python3.5/site-packages/gunicorn/arbiter.py", line 583, in spawn_worker
    worker.init_process()
  File "/home/intel/.local/lib/python3.5/site-packages/gunicorn/workers/base.py", line 129, in init_process
    self.load_wsgi()
  File "/home/intel/.local/lib/python3.5/site-packages/gunicorn/workers/base.py", line 138, in load_wsgi
    self.wsgi = self.app.wsgi()
  File "/home/intel/.local/lib/python3.5/site-packages/gunicorn/app/base.py", line 67, in wsgi
    self.callable = self.load()
  File "/home/intel/.local/lib/python3.5/site-packages/gunicorn/app/wsgiapp.py", line 52, in load
    return self.load_wsgiapp()
  File "/home/intel/.local/lib/python3.5/site-packages/gunicorn/app/wsgiapp.py", line 41, in load_wsgiapp
    return util.import_app(self.app_uri)
  File "/home/intel/.local/lib/python3.5/site-packages/gunicorn/util.py", line 350, in import_app
    __import__(module)
  File "/home/intel/xytao/hsdes.py", line 64
    response_str = self.session.get(
               ^
IndentationError: expected an indented block
[2018-09-19 15:46:51 +0800] [16003] [INFO] Worker exiting (pid: 16003)
[2018-09-19 15:46:51 +0800] [16000] [INFO] Shutting down: Master
[2018-09-19 15:46:51 +0800] [16000] [INFO] Reason: Worker failed to boot.
[2018-09-19 15:46:53 +0800] [16004] [INFO] Starting gunicorn 19.9.0
[2018-09-19 15:46:53 +0800] [16004] [INFO] Listening at: http://0.0.0.0:2345 (16004)
[2018-09-19 15:46:53 +0800] [16004] [INFO] Using worker: sync
[2018-09-19 15:46:53 +0800] [16007] [INFO] Booting worker with pid: 16007
[2018-09-19 15:46:53 +0800] [16007] [ERROR] Exception in worker process
Traceback (most recent call last):
  File "/home/intel/.local/lib/python3.5/site-packages/gunicorn/arbiter.py", line 583, in spawn_worker
    worker.init_process()
  File "/home/intel/.local/lib/python3.5/site-packages/gunicorn/workers/base.py", line 129, in init_process
    self.load_wsgi()
  File "/home/intel/.local/lib/python3.5/site-packages/gunicorn/workers/base.py", line 138, in load_wsgi
    self.wsgi = self.app.wsgi()
  File "/home/intel/.local/lib/python3.5/site-packages/gunicorn/app/base.py", line 67, in wsgi
    self.callable = self.load()
  File "/home/intel/.local/lib/python3.5/site-packages/gunicorn/app/wsgiapp.py", line 52, in load
    return self.load_wsgiapp()
  File "/home/intel/.local/lib/python3.5/site-packages/gunicorn/app/wsgiapp.py", line 41, in load_wsgiapp
    return util.import_app(self.app_uri)
  File "/home/intel/.local/lib/python3.5/site-packages/gunicorn/util.py", line 350, in import_app
    __import__(module)
  File "/home/intel/xytao/hsdes.py", line 64
    response_str = self.session.get(
               ^
IndentationError: expected an indented block
[2018-09-19 15:46:53 +0800] [16007] [INFO] Worker exiting (pid: 16007)
[2018-09-19 15:46:53 +0800] [16004] [INFO] Shutting down: Master
[2018-09-19 15:46:53 +0800] [16004] [INFO] Reason: Worker failed to boot.
[2018-09-19 15:46:55 +0800] [16008] [INFO] Starting gunicorn 19.9.0
[2018-09-19 15:46:55 +0800] [16008] [INFO] Listening at: http://0.0.0.0:2345 (16008)
[2018-09-19 15:46:55 +0800] [16008] [INFO] Using worker: sync
[2018-09-19 15:46:55 +0800] [16011] [INFO] Booting worker with pid: 16011
[2018-09-19 15:46:55 +0800] [16011] [ERROR] Exception in worker process
Traceback (most recent call last):
  File "/home/intel/.local/lib/python3.5/site-packages/gunicorn/arbiter.py", line 583, in spawn_worker
    worker.init_process()
  File "/home/intel/.local/lib/python3.5/site-packages/gunicorn/workers/base.py", line 129, in init_process
    self.load_wsgi()
  File "/home/intel/.local/lib/python3.5/site-packages/gunicorn/workers/base.py", line 138, in load_wsgi
    self.wsgi = self.app.wsgi()
  File "/home/intel/.local/lib/python3.5/site-packages/gunicorn/app/base.py", line 67, in wsgi
    self.callable = self.load()
  File "/home/intel/.local/lib/python3.5/site-packages/gunicorn/app/wsgiapp.py", line 52, in load
    return self.load_wsgiapp()
  File "/home/intel/.local/lib/python3.5/site-packages/gunicorn/app/wsgiapp.py", line 41, in load_wsgiapp
    return util.import_app(self.app_uri)
  File "/home/intel/.local/lib/python3.5/site-packages/gunicorn/util.py", line 350, in import_app
    __import__(module)
  File "/home/intel/xytao/hsdes.py", line 64
    response_str = self.session.get(
               ^
IndentationError: expected an indented block
[2018-09-19 15:46:55 +0800] [16011] [INFO] Worker exiting (pid: 16011)
[2018-09-19 15:46:55 +0800] [16008] [INFO] Shutting down: Master
[2018-09-19 15:46:55 +0800] [16008] [INFO] Reason: Worker failed to boot.
[2018-09-19 15:46:59 +0800] [16012] [INFO] Starting gunicorn 19.9.0
[2018-09-19 15:46:59 +0800] [16012] [INFO] Listening at: http://0.0.0.0:2345 (16012)
[2018-09-19 15:46:59 +0800] [16012] [INFO] Using worker: sync
[2018-09-19 15:46:59 +0800] [16015] [INFO] Booting worker with pid: 16015
[2018-09-19 15:46:59 +0800] [16015] [ERROR] Exception in worker process
Traceback (most recent call last):
  File "/home/intel/.local/lib/python3.5/site-packages/gunicorn/arbiter.py", line 583, in spawn_worker
    worker.init_process()
  File "/home/intel/.local/lib/python3.5/site-packages/gunicorn/workers/base.py", line 129, in init_process
    self.load_wsgi()
  File "/home/intel/.local/lib/python3.5/site-packages/gunicorn/workers/base.py", line 138, in load_wsgi
    self.wsgi = self.app.wsgi()
  File "/home/intel/.local/lib/python3.5/site-packages/gunicorn/app/base.py", line 67, in wsgi
    self.callable = self.load()
  File "/home/intel/.local/lib/python3.5/site-packages/gunicorn/app/wsgiapp.py", line 52, in load
    return self.load_wsgiapp()
  File "/home/intel/.local/lib/python3.5/site-packages/gunicorn/app/wsgiapp.py", line 41, in load_wsgiapp
    return util.import_app(self.app_uri)
  File "/home/intel/.local/lib/python3.5/site-packages/gunicorn/util.py", line 350, in import_app
    __import__(module)
  File "/home/intel/xytao/hsdes.py", line 64
    response_str = self.session.get(
               ^
IndentationError: expected an indented block
[2018-09-19 15:46:59 +0800] [16015] [INFO] Worker exiting (pid: 16015)
[2018-09-19 15:46:59 +0800] [16012] [INFO] Shutting down: Master
[2018-09-19 15:46:59 +0800] [16012] [INFO] Reason: Worker failed to boot.
